Workbook

Sheet PH-Phases
A1: Phase ID | B1: Phase Name | C1: Summary | D1: Goals | E1: Objectives
A2: PH-01 | B2: Full Conversion (Decision-Centric Core) | C2: Deliver the core decision engine for contract-first ordering, pricing enforcement, and rule-driven fulfillment to replace spreadsheets and tribal knowledge. | D2: Enforce contracts and pricing at order time; Execute compliant fulfillment without manual interpretation | E2: Orders are created with correct pricing and terms on first pass; Manual contract validation is eliminated for standard orders; Pricing, approval, and substitution decisions are fully auditable
A3: PH-02 | B3: Automation (Operational Scale) | C3: Automate exception handling, approvals, and multi-source fulfillment to increase throughput and reduce operational firefighting. | D3: Reduce operational escalations and manual intervention; Increase order throughput without additional headcount | E3: Majority of orders process without manual escalation; Automated approvals handle most margin and compliance thresholds; Fulfillment routing executes consistently across warehouses
A4: PH-03 | B4: Scale (Predictability & Expansion) | C4: Extend the OMS to support new warehouses, vendors, regulations, and analytics with confidence and predictable financial outcomes. | D4: Enable rapid expansion without increasing compliance or margin risk; Improve forecasting accuracy and financial predictability | E4: New warehouses and vendors onboard with minimal configuration effort; Demand, margin, and service-level forecasting is reliable; Audit readiness is achieved without manual reconciliation

Sheet DEL-Deliverables
A1: Deliverable ID | B1: Strategy Ref | C1: Blueprint Ref | D1: Phase Ref ID | E1: Requirement Type | F1: Deliverable Name | G1: Deliverable Description | H1: Notes | I1: Complexity | J1: Effort | K1: Hours | L1: Epic Roll-Up | M1: ELI Roll-Up
A2: DEL-001 | B2: CAP-001 | C2: BP-1765865704672 | D2: PH-01 | E2: Experience | F2: Contract Management | G2: Manage customer profiles, contracts, service terms, and compliance requirements so orders are evaluated against the correct agreements and constraints. | I2: Medium | J2: 8 | K2: 120 | L2: 3 | M2: 9
A3: DEL-002 | B3: CAP-002 | C3: BP-1765865704672 | D3: PH-01 | E3: Experience | F3: Inventory Management | G3: Provide real-time visibility and control over inventory across warehouses and vendor sources to support accurate sourcing, allocation, and fulfillment decisions. | I3: Medium | J3: 8 | K3: 120 | L3: 3 | M3: 9
A4: DEL-003 | B4: CAP-003 | C4: BP-1765865704672 | D4: PH-01 | E4: Experience | F4: Order Management | G4: Create, validate, and manage sales orders with contract-first pricing and controlled lifecycle changes enforced at order time. | I4: High | J4: 13 | K4: 160 | L4: 4 | M4: 12
A5: DEL-004 | B5: CAP-004 | C5: BP-1765865704672 | D5: PH-01 | E5: Experience | F5: Fulfillment Orchestration | G5: Orchestrate compliant, rule-driven fulfillment across warehouses and vendors by applying rules for splits, substitutions, and service levels. | I5: High | J5: 13 | K5: 160 | L5: 3 | M5: 9
A6: DEL-005 | B6: CAP-005 | C6: BP-1765865704672 | D6: PH-01 | E6: Experience | F6: Purchase Management | G6: Coordinate purchasing from vendors based on demand, inventory gaps, and contract terms to ensure supply decisions align with pricing, compliance, and margin goals. | I6: Medium | J6: 8 | K6: 100 | L6: 3 | M6: 9
A7: DEL-006 | B7: CAP-006 | C7: BP-1765865704672 | D7: PH-01 | E7: Workflow | F7: Sales Order Processing | G7: Create, validate, price, and route sales orders through approvals to a “ready for fulfillment” state with full auditability. | I7: High | J7: 13 | K7: 140 | L7: 1 | M7: 5
A8: DEL-007 | B8: CAP-007 | C8: BP-1765865704672 | D8: PH-01 | E8: Workflow | F8: Fulfillment Execution | G8: Route fulfillment, allocate inventory, generate pick/pack/ship instructions, and confirm shipment with auditability. | I8: High | J8: 13 | K8: 100 | L8: 1 | M8: 5
A9: DEL-008 | B9: CAP-008 | C9: BP-1765865704672 | D9: PH-01 | E9: Workflow | F9: Purchase Replenishment | G9: Identify supply gaps, source eligible vendors, create POs with contract terms, receive goods, and close POs. | I9: Medium | J9: 8 | K9: 60 | L9: 1 | M9: 3
A10: DEL-009 | B10: FOUNDATIONS | C10: BP-1765865704672 | D10: PH-01 | E10: Foundation | F10: Foundations | G10: Infrastructure and foundational systems | K10: 160 | L10: 6 | M10: 18
A11: DEL-010 | B11: FUNC-031 | C11: BP-1765865704672 | D11: PH-01 | E11: Integration | F11: Inventory / WMS Service | G11: Source of truth for on-hand/available inventory and the execution surface for reservations and receiving updates. | I11: High | J11: 8 | K11: 40 | L11: 1 | M11: 1
A12: DEL-011 | B12: FUNC-032 | C12: BP-1765865704672 | D12: PH-01 | E12: Integration | F12: Vendor Portal / Supplier API | G12: External vendor system(s) providing item availability, lead times, SLAs, and certification status for sourcing and substitution decisions. | I12: High | J12: 8 | K12: 60 | L12: 1 | M12: 1
A13: DEL-012 | B13: FUNC-033 | C13: BP-1765865704672 | D13: PH-01 | E13: Integration | F13: Compliance Rules & Restrictions Service | G13: External or internal service that returns compliance rules, geo restrictions, and item-level regulatory attributes for evaluation at order and substitution time. | I13: High | J13: 8 | K13: 60 | L13: 1 | M13: 1
A14: DEL-013 | B14: FUNC-034 | C14: BP-1765865704672 | D14: PH-01 | E14: Integration | F14: Messaging / Event Bus | G14: Central eventing platform used to publish OMS domain events for consumers (ERP integration workers, dashboards, notifications). | I14: Medium | J14: 5 | K14: 40 | L14: 1 | M14: 1

Sheet EPIC - Epics
A1: Epic ID | B1: Strategy Ref | C1: Blueprint Ref | D1: Phase Ref ID | E1: Deliverable ID | F1: Deliverable Name | G1: Epic Type | H1: Epic Name | I1: Epic User Story | J1: Notes | K1: Complexity | L1: Effort | M1: Hours | N1: ELI Roll-Up
A2: EPIC-001 | B2: CAP-006 | C2: BP-1765865704672 | D2: PH-01 | E2: DEL-006 | F2: Sales Order Processing | G2: Workflow | H2: Sales Order Processing | I2: Create, validate, price, and route sales orders through approvals to a “ready for fulfillment” state with full auditability. | K2: High | L2: 13 | N2: 5
A3: EPIC-002 | B3: CAP-007 | C3: BP-1765865704672 | D3: PH-01 | E3: DEL-007 | F3: Fulfillment Execution | G3: Workflow | H3: Fulfillment Execution | I3: Route fulfillment, allocate inventory, generate pick/pack/ship instructions, and confirm shipment with auditability. | K3: High | L3: 13 | N3: 5
A4: EPIC-003 | B4: CAP-008 | C4: BP-1765865704672 | D4: PH-01 | E4: DEL-008 | F4: Purchase Replenishment | G4: Workflow | H4: Purchase Replenishment | I4: Identify supply gaps, source eligible vendors, create POs with contract terms, receive goods, and close POs. | K4: Medium | L4: 8 | N4: 3
A5: EPIC-004 | B5: CAP-014 | C5: BP-1765865704672 | D5: PH-01 | E5: DEL-009 | F5: Foundations | G5: Foundation | H5: Navigation and Component Library | I5: Establish the visual framework and reusable building blocks that define the application's user experience across OMS screens. | K5: Medium | L5: 8 | N5: 3
A6: EPIC-005 | B6: CAP-015 | C6: BP-1765865704672 | D6: PH-01 | E6: DEL-009 | F6: Foundations | G6: Foundation | H6: User Management | I6: Set up systems to onboard, store, and manage user accounts so each OMS user has an identity tied to permissions and settings. | K6: Medium | L6: 8 | N6: 3
A7: EPIC-006 | B7: CAP-016 | C7: BP-1765865704672 | D7: PH-01 | E7: DEL-009 | F7: Foundations | G7: Foundation | H7: Authentication & Security | I7: Protect OMS access with secure login flows, API protection, and encryption for sensitive contract, pricing, and compliance data. | K7: High | L7: 13 | N7: 3
A8: EPIC-007 | B8: CAP-017 | C8: BP-1765865704672 | D8: PH-01 | E8: DEL-009 | F8: Foundations | G8: Foundation | H8: Data Management | I8: Establish OMS core data models and APIs to support customers, contracts, orders, inventory reservations, fulfillment events, and purchasing. | K8: High | L8: 13 | N8: 3
A9: EPIC-008 | B9: CAP-018 | C9: BP-1765865704672 | D9: PH-01 | E9: DEL-009 | F9: Foundations | G9: Foundation | H9: Backend Infrastructure | I9: Provide core runtime, APIs, messaging, observability, and operational safeguards required to run OMS reliably across workflows and integrations. | K9: High | L9: 13 | N9: 3
A10: EPIC-009 | B10: CAP-019 | C10: BP-1765865704672 | D10: PH-01 | E10: DEL-009 | F10: Foundations | G10: Foundation | H10: DevOps | I10: Enable smooth development, deployment, and maintenance workflows across environments (local, staging, production) for OMS. | K10: Medium | L10: 8 | N10: 3
A11: EPIC-010 | B11: FUNC-001 | C11: BP-1765865704672 | D11: PH-01 | E11: DEL-001 | F11: Customer Management | G11: Use Case | H11: Manage Customers | I11: Create, update, and search customer profiles used for order association and downstream enforcement. | K11: Medium | L11: 5 | N11: 3
A12: EPIC-011 | B12: FUNC-002 | C12: BP-1765865704672 | D12: PH-01 | E12: DEL-001 | F12: Customer Management | G12: Use Case | H12: Associate Contracts to Customers | I12: Link active contracts to customers so pricing, terms, and decisioning are enforced at order time. | K12: High | L12: 8 | N12: 3
A13: EPIC-012 | B13: FUNC-003 | C13: BP-1765865704672 | D13: PH-01 | E13: DEL-001 | F13: Customer Management | G13: Use Case | H13: Manage Customer Compliance Requirements | I13: Define and apply customer-specific compliance constraints and maintain an auditable trail of compliance decisions. | K13: High | L13: 8 | N13: 3
... A30: EPIC-029 | B30: FUNC-034 | C30: BP-1765865704672 | D30: PH-01 | E30: DEL-013 | F30: Messaging / Event Bus | G30: System | H30: Messaging / Event Bus | I30: Central eventing platform used to publish OMS domain events for consumers (ERP integration workers, dashboards, notifications). | K30: Medium | L30: 5 | N30: 1

Sheet UG - User Groups
A1: User Group ID | B1: Name | C1: Description | D1: Objectives | E1: Challenges | F1: Benefits | G1: High Level User Story
A2: UG-01 | B2: Sales / Account Management | C2: Owns customer relationships and initiates sales orders, ensuring accurate customer context, pricing visibility, and contract alignment at order time. | D2: Create and submit accurate sales orders quickly; Ensure contract pricing is applied correctly on first pass; Respond confidently to customer questions and changes | E2: Contract logic historically scattered across spreadsheets and emails; Risk of quoting incorrect pricing or terms; Dependence on Ops or Finance for validations | F2: Faster order entry with fewer escalations; Higher order accuracy and customer trust; Clear visibility into pricing and approvals | G2: As a/An Sales / Account Management, I want Create and submit accurate sales orders quickly so that Faster order entry with fewer escalations.
A3: UG-02 | B3: Operations / Order Management | C3: Orchestrates order execution and exception handling, translating complex business rules into consistent fulfillment outcomes. | D3: Execute complex orders with system-driven decisions; Reduce manual intervention and operational firefighting; Ensure routing, sourcing, and substitutions follow rules and SLAs | E3: Reliance on tribal knowledge for fulfillment decisions; Multi-source fulfillment complexity; Frequent exceptions requiring rework | F3: Repeatable and predictable order execution; Fewer escalations and handoffs; Clear audit trail for operational decisions | G3: As a/An Operations / Order Management, I want Execute complex orders with system-driven decisions so that Repeatable and predictable order execution.
A4: UG-03 | B4: Warehouse & Fulfillment | C4: Executes picking, packing, shipping, and receiving activities across warehouses using system-generated instructions. | D4: Fulfill orders accurately and efficiently; Maintain inventory accuracy through timely updates; Execute substitutions and splits correctly | E4: Limited visibility into upstream decision context; Increased error risk from multi-warehouse splits; Inventory discrepancies due to delayed updates | F4: Clear pick/pack/ship instructions; Reduced fulfillment errors and rework; Faster throughput and inventory accuracy | G4: As a/An Warehouse & Fulfillment, I want Fulfill orders accurately and efficiently so that Clear pick/pack/ship instructions.
A5: UG-04 | B5: Finance / Compliance / Admin | C5: Governs pricing, approvals, compliance, and auditability to protect margins, ensure regulatory adherence, and maintain system integrity. | D5: Enforce contract pricing, approvals, and overrides; Maintain audit-ready records for pricing and compliance; Govern changes to contracts, rules, and vendors safely | E5: Margin erosion detected too late in the process; Manual audit preparation using spreadsheets; Risk when critical logic lives outside core systems | F5: Predictable margin protection; Clear, defensible audit trails; Centralized governance of rules and decisions | G5: As a/An Finance / Compliance / Admin, I want Enforce contract pricing, approvals, and overrides so that Predictable margin protection.

Sheet User Stories
A1: ELI ID | B1: deliverable | C1: epic | D1: Description | E1: as the | F1: I want to | G1: so i can | H1: Phase | I1: Tech Notes | J1: complexity | K1: hours | L1: sa | M1: qa | N1: total
A2: ELI-001 | B2: {=INDEX('ELI Data File'!I:I, MATCH(A2, 'ELI Data File'!A:A, 0))} -> Customer Management | C2: {=INDEX('ELI Data File'!J:J, MATCH(A2, 'ELI Data File'!A:A, 0))} -> Manage Customers | D2: {=INDEX('ELI Data File'!M:M, MATCH(A2, 'ELI Data File'!A:A, 0))} -> As a Sales user, I want to create a customer profile so that orders can be associated with the correct legal and billing entity. | E2: {=INDEX('ELI Data File'!H:H, MATCH(A2, 'ELI Data File'!A:A, 0))} -> Sales / Account Management | F2: =IFERROR(__xludf.DUMMYFUNCTION("AI(""Extract the Goal from the description""&D2)"),"create a customer profile") -> create a customer profile | G2: =IFERROR(__xludf.DUMMYFUNCTION("AI(""Extract the Value from the description""&D2)"),"orders can be associated with the correct legal and billing entity.") -> orders can be associated with the correct legal and billing entity. | H2: {=INDEX('ELI Data File'!D:D, MATCH(A2, 'ELI Data File'!A:A, 0))} -> PH-01 | J2: {=INDEX('ELI Data File'!O:O, MATCH(A2, 'ELI Data File'!A:A, 0))} -> Medium | K2: {=INDEX('ELI Data File'!P:P, MATCH(A2, 'ELI Data File'!A:A, 0))*4} -> 12 | L2: =ROUNDUP(K2*0.2,0) -> 3 | M2: 1 | N2: =SUM(K2:M2) -> 16
A3: ELI-002 | B3: {=INDEX('ELI Data File'!I:I, MATCH(A3, 'ELI Data File'!A:A, 0))} -> Customer Management | C3: {=INDEX('ELI Data File'!J:J, MATCH(A3, 'ELI Data File'!A:A, 0))} -> Manage Customers | D3: {=INDEX('ELI Data File'!M:M, MATCH(A3, 'ELI Data File'!A:A, 0))} -> As a Sales user, I want to update customer details so changes are reflected in future orders. | E3: {=INDEX('ELI Data File'!H:H, MATCH(A3, 'ELI Data File'!A:A, 0))} -> Sales / Account Management | F3: =IFERROR(__xludf.DUMMYFUNCTION("AI(""Extract the Goal from the description""&D3)"),"update customer details") -> update customer details | G3: =IFERROR(__xludf.DUMMYFUNCTION("AI(""Extract the Value from the description""&D3)"),"changes are reflected in future orders") -> changes are reflected in future orders | H3: {=INDEX('ELI Data File'!D:D, MATCH(A3, 'ELI Data File'!A:A, 0))} -> PH-01 | J3: {=INDEX('ELI Data File'!O:O, MATCH(A3, 'ELI Data File'!A:A, 0))} -> Medium | K3: {=INDEX('ELI Data File'!P:P, MATCH(A3, 'ELI Data File'!A:A, 0))*4} -> 12 | L3: =ROUNDUP(K3*0.2,0) -> 3 | M3: =ROUNDDOWN(SUM(K3:L3)/3,0) -> 5 | N3: =SUM(K3:M3) -> 20
A4: ELI-003 | B4: {=INDEX('ELI Data File'!I:I, MATCH(A4, 'ELI Data File'!A:A, 0))} -> Customer Management | C4: {=INDEX('ELI Data File'!J:J, MATCH(A4, 'ELI Data File'!A:A, 0))} -> Manage Customers | D4: {=INDEX('ELI Data File'!M:M, MATCH(A4, 'ELI Data File'!A:A, 0))} -> As an Ops user, I want to search customers quickly so I can validate order context without manual lookup. | E4: {=INDEX('ELI Data File'!H:H, MATCH(A4, 'ELI Data File'!A:A, 0))} -> Operations / Order Management | F4: =IFERROR(__xludf.DUMMYFUNCTION("AI(""Extract the Goal from the description""&D4)"),"search customers quickly") -> search customers quickly | G4: =IFERROR(__xludf.DUMMYFUNCTION("AI(""Extract the Value from the description""&D4)"),"validate order context without manual lookup.") -> validate order context without manual lookup. | H4: {=INDEX('ELI Data File'!D:D, MATCH(A4, 'ELI Data File'!A:A, 0))} -> PH-01 | J4: {=INDEX('ELI Data File'!O:O, MATCH(A4, 'ELI Data File'!A:A, 0))} -> Medium | K4: {=INDEX('ELI Data File'!P:P, MATCH(A4, 'ELI Data File'!A:A, 0))*4} -> 12 | L4: =ROUNDUP(K4*0.2,0) -> 3 | M4: =ROUNDDOWN(SUM(K4:L4)/3,0) -> 5 | N4: =SUM(K4:M4) -> 20
A5: ELI-004 | B5: {=INDEX('ELI Data File'!I:I, MATCH(A5, 'ELI Data File'!A:A, 0))} -> Customer Management | C5: {=INDEX('ELI Data File'!J:J, MATCH(A5, 'ELI Data File'!A:A, 0))} -> Associate Contracts to Customers | D5: {=INDEX('ELI Data File'!M:M, MATCH(A5, 'ELI Data File'!A:A, 0))} -> As an Admin, I want to associate an active contract to a customer so pricing and terms are enforced at order time. | E5: {=INDEX('ELI Data File'!H:H, MATCH(A5, 'ELI Data File'!A:A, 0))} -> Finance / Compliance / Admin | F5: =IFERROR(__xludf.DUMMYFUNCTION("AI(""Extract the Goal from the description""&D5)"),"associate an active contract to a customer") -> associate an active contract to a customer | G5: =IFERROR(__xludf.DUMMYFUNCTION("AI(""Extract the Value from the description""&D5)"),"pricing and terms are enforced at order time.") -> pricing and terms are enforced at order time. | H5: {=INDEX('ELI Data File'!D:D, MATCH(A5, 'ELI Data File'!A:A, 0))} -> PH-01 | J5: {=INDEX('ELI Data File'!O:O, MATCH(A5, 'ELI Data File'!A:A, 0))} -> Medium | K5: {=INDEX('ELI Data File'!P:P, MATCH(A5, 'ELI Data File'!A:A, 0))*4} -> 12 | L5: =ROUNDUP(K5*0.2,0) -> 3 | M5: =ROUNDDOWN(SUM(K5:L5)/3,0) -> 5 | N5: =SUM(K5:M5) -> 20
A6: ELI-005 | B6: {=INDEX('ELI Data File'!I:I, MATCH(A6, 'ELI Data File'!A:A, 0))} -> Customer Management | C6: {=INDEX('ELI Data File'!J:J, MATCH(A6, 'ELI Data File'!A:A, 0))} -> Associate Contracts to Customers | D6: {=INDEX('ELI Data File'!M:M, MATCH(A6, 'ELI Data File'!A:A, 0))} -> As Finance, I want to prevent orders for customers without active contracts to avoid uncontrolled pricing. | E6: {=INDEX('ELI Data File'!H:H, MATCH(A6, 'ELI Data File'!A:A, 0))} -> Finance / Compliance / Admin | F6: =IFERROR(__xludf.DUMMYFUNCTION("AI(""Extract the Goal from the description""&D6)"),"prevent orders for customers without active contracts") -> prevent orders for customers without active contracts | G6: =IFERROR(__xludf.DUMMYFUNCTION("AI(""Extract the Value from the description""&D6)"),"avoid uncontrolled pricing") -> avoid uncontrolled pricing | H6: {=INDEX('ELI Data File'!D:D, MATCH(A6, 'ELI Data File'!A:A, 0))} -> PH-01 | J6: {=INDEX('ELI Data File'!O:O, MATCH(A6, 'ELI Data File'!A:A, 0))} -> Medium | K6: {=INDEX('ELI Data File'!P:P, MATCH(A6, 'ELI Data File'!A:A, 0))*4} -> 12 | L6: =ROUNDUP(K6*0.2,0) -> 3 | M6: =ROUNDDOWN(SUM(K6:L6)/3,0) -> 5 | N6: =SUM(K6:M6) -> 20
A7: ELI-006 | B7: {=INDEX('ELI Data File'!I:I, MATCH(A7, 'ELI Data File'!A:A, 0))} -> Customer Management | C7: {=INDEX('ELI Data File'!J:J, MATCH(A7, 'ELI Data File'!A:A, 0))} -> Associate Contracts to Customers | D7: {=INDEX('ELI Data File'!M:M, MATCH(A7, 'ELI Data File'!A:A, 0))} -> As Finance, I want to view contract assignment history so audits do not rely on spreadsheets. | E7: {=INDEX('ELI Data File'!H:H, MATCH(A7, 'ELI Data File'!A:A, 0))} -> Finance / Compliance / Admin | F7: =IFERROR(__xludf.DUMMYFUNCTION("AI(""Extract the Goal from the description""&D7)"),"view contract assignment history") -> view contract assignment history | G7: =IFERROR(__xludf.DUMMYFUNCTION("AI(""Extract the Value from the description""&D7)"),"audits do not rely on spreadsheets.") -> audits do not rely on spreadsheets. | H7: {=INDEX('ELI Data File'!D:D, MATCH(A7, 'ELI Data File'!A:A, 0))} -> PH-01 | J7: {=INDEX('ELI Data File'!O:O, MATCH(A7, 'ELI Data File'!A:A, 0))} -> Medium | K7: {=INDEX('ELI Data File'!P:P, MATCH(A7, 'ELI Data File'!A:A, 0))*4} -> 12 | L7: =ROUNDUP(K7*0.2,0) -> 3 | M7: =ROUNDDOWN(SUM(K7:L7)/3,0) -> 5 | N7: =SUM(K7:M7) -> 20
A8: ELI-007 | B8: {=INDEX('ELI Data File'!I:I, MATCH(A8, 'ELI Data File'!A:A, 0))} -> Customer Management | C8: {=INDEX('ELI Data File'!J:J, MATCH(A8, 'ELI Data File'!A:A, 0))} -> Manage Customer Compliance Requirements | D8: {=INDEX('ELI Data File'!M:M, MATCH(A8, 'ELI Data File'!A:A, 0))} -> As a Compliance admin, I want to define customer-specific compliance rules so non-compliant orders are blocked. | E8: {=INDEX('ELI Data File'!H:H, MATCH(A8, 'ELI Data File'!A:A, 0))} -> Finance / Compliance / Admin | F8: =IFERROR(__xludf.DUMMYFUNCTION("AI(""Extract the Goal from the description""&D8)"),"define customer-specific compliance rules") -> define customer-specific compliance rules | G8: =IFERROR(__xludf.DUMMYFUNCTION("AI(""Extract the Value from the description""&D8)"),"non-compliant orders are blocked.") -> non-compliant orders are blocked. | H8: {=INDEX('ELI Data File'!D:D, MATCH(A8, 'ELI Data File'!A:A, 0))} -> PH-01 | J8: {=INDEX('ELI Data File'!O:O, MATCH(A8, 'ELI Data File'!A:A, 0))} -> Medium | K8: {=INDEX('ELI Data File'!P:P, MATCH(A8, 'ELI Data File'!A:A, 0))*4} -> 12 | L8: =ROUNDUP(K8*0.2,0) -> 3 | M8: =ROUNDDOWN(SUM(K8:L8)/3,0) -> 5 | N8: =SUM(K8:M8) -> 20
A9: ELI-008 | B9: {=INDEX('ELI Data File'!I:I, MATCH(A9, 'ELI Data File'!A:A, 0))} -> Customer Management | C9: {=INDEX('ELI Data File'!J:J, MATCH(A9, 'ELI Data File'!A:A, 0))} -> Manage Customer Compliance Requirements | D9: {=INDEX('ELI Data File'!M:M, MATCH(A9, 'ELI Data File'!A:A, 0))} -> As Ops, I want compliance rules evaluated automatically so I don’t interpret regulations manually. | E9: {=INDEX('ELI Data File'!H:H, MATCH(A9, 'ELI Data File'!A:A, 0))} -> Operations / Order Management | F9: =IFERROR(__xludf.DUMMYFUNCTION("AI(""Extract the Goal from the description""&D9)"),"compliance rules evaluated automatically") -> compliance rules evaluated automatically | G9: =IFERROR(__xludf.DUMMYFUNCTION("AI(""Extract the Value from the description""&D9)"),"I don’t interpret regulations manually.") -> I don’t interpret regulations manually. | H9: {=INDEX('ELI Data File'!D:D, MATCH(A9, 'ELI Data File'!A:A, 0))} -> PH-01 | J9: {=INDEX('ELI Data File'!O:O, MATCH(A9, 'ELI Data File'!A:A, 0))} -> Medium | K9: {=INDEX('ELI Data File'!P:P, MATCH(A9, 'ELI Data File'!A:A, 0))*4} -> 12 | L9: =ROUNDUP(K9*0.2,0) -> 3 | M9: =ROUNDDOWN(SUM(K9:L9)/3,0) -> 5 | N9: =SUM(K9:M9) -> 20
A10: ELI-009 | B10: {=INDEX('ELI Data File'!I:I, MATCH(A10, 'ELI Data File'!A:A, 0))} -> Customer Management | C10: {=INDEX('ELI Data File'!J:J, MATCH(A10, 'ELI Data File'!A:A, 0))} -> Manage Customer Compliance Requirements | D10: {=INDEX('ELI Data File'!M:M, MATCH(A10, 'ELI Data File'!A:A, 0))} -> As Compliance, I want an audit trail of compliance decisions so regulatory reviews are defensible. | E10: {=INDEX('ELI Data File'!H:H, MATCH(A10, 'ELI Data File'!A:A, 0))} -> Finance / Compliance / Admin | F10: =IFERROR(__xludf.DUMMYFUNCTION("AI(""Extract the Goal from the description""&D10)"),"want an audit trail of compliance decisions") -> want an audit trail of compliance decisions | G10: =IFERROR(__xludf.DUMMYFUNCTION("AI(""Extract the Value from the description""&D10)"),"regulatory reviews are defensible") -> regulatory reviews are defensible | H10: {=INDEX('ELI Data File'!D:D, MATCH(A10, 'ELI Data File'!A:A, 0))} -> PH-01 | J10: {=INDEX('ELI Data File'!O:O, MATCH(A10, 'ELI Data File'!A:A, 0))} -> Medium | K10: {=INDEX('ELI Data File'!P:P, MATCH(A10, 'ELI Data File'!A:A, 0))*4} -> 12 | L10: =ROUNDUP(K10*0.2,0) -> 3 | M10: =ROUNDDOWN(SUM(K10:L10)/3,0) -> 5 | N10: =SUM(K10:M10) -> 20
A11: ELI-010 | B11: {=INDEX('ELI Data File'!I:I, MATCH(A11, 'ELI Data File'!A:A, 0))} -> Inventory Management | C11: {=INDEX('ELI Data File'!J:J, MATCH(A11, 'ELI Data File'!A:A, 0))} -> Manage Inventory | D11: {=INDEX('ELI Data File'!M:M, MATCH(A11, 'ELI Data File'!A:A, 0))} -> As an Ops user, I want to view real-time inventory levels so I can make accurate fulfillment decisions. | E11: {=INDEX('ELI Data File'!H:H, MATCH(A11, 'ELI Data File'!A:A, 0))} -> Operations / Order Management | F11: =IFERROR(__xludf.DUMMYFUNCTION("AI(""Extract the Goal from the description""&D11)"),"view real-time inventory levels") -> view real-time inventory levels | G11: =IFERROR(__xludf.DUMMYFUNCTION("AI(""Extract the Value from the description""&D11)"),"so I can make accurate fulfillment decisions.") -> so I can make accurate fulfillment decisions. | H11: {=INDEX('ELI Data File'!D:D, MATCH(A11, 'ELI Data File'!A:A, 0))} -> PH-01 | J11: {=INDEX('ELI Data File'!O:O, MATCH(A11, 'ELI Data File'!A:A, 0))} -> Medium | K11: {=INDEX('ELI Data File'!P:P, MATCH(A11, 'ELI Data File'!A:A, 0))*4} -> 12 | L11: =ROUNDUP(K11*0.2,0) -> 3 | M11: =ROUNDDOWN(SUM(K11:L11)/3,0) -> 5 | N11: =SUM(K11:M11) -> 20
A12: ELI-011 | B12: {=INDEX('ELI Data File'!I:I, MATCH(A12, 'ELI Data File'!A:A, 0))} -> Inventory Management | C12: {=INDEX('ELI Data File'!J:J, MATCH(A12, 'ELI Data File'!A:A, 0))} -> Manage Inventory | D12: {=INDEX('ELI Data File'!M:M, MATCH(A12, 'ELI Data File'!A:A, 0))} -> As a Warehouse user, I want to adjust inventory quantities so physical discrepancies are reflected in the system. | E12: {=INDEX('ELI Data File'!H:H, MATCH(A12, 'ELI Data File'!A:A, 0))} -> Warehouse & Fulfillment | F12: =IFERROR(__xludf.DUMMYFUNCTION("AI(""Extract the Goal from the description""&D12)"),"adjust inventory quantities") -> adjust inventory quantities | G12: =IFERROR(__xludf.DUMMYFUNCTION("AI(""Extract the Value from the description""&D12)"),"physical discrepancies are reflected in the system.") -> physical discrepancies are reflected in the system. | H12: {=INDEX('ELI Data File'!D:D, MATCH(A12, 'ELI Data File'!A:A, 0))} -> PH-01 | J12: {=INDEX('ELI Data File'!O:O, MATCH(A12, 'ELI Data File'!A:A, 0))} -> Medium | K12: {=INDEX('ELI Data File'!P:P, MATCH(A12, 'ELI Data File'!A:A, 0))*4} -> 12 | L12: =ROUNDUP(K12*0.2,0) -> 3 | M12: =ROUNDDOWN(SUM(K12:L12)/3,0) -> 5 | N12: =SUM(K12:M12) -> 20
A13: ELI-012 | B13: {=INDEX('ELI Data File'!I:I, MATCH(A13, 'ELI Data File'!A:A, 0))} -> Inventory Management | C13: {=INDEX('ELI Data File'!J:J, MATCH(A13, 'ELI Data File'!A:A, 0))} -> Manage Inventory | D13: {=INDEX('ELI Data File'!M:M, MATCH(A13, 'ELI Data File'!A:A, 0))} -> As a Warehouse user, I want to receive inventory so newly arrived stock becomes available for allocation. | E13: {=INDEX('ELI Data File'!H:H, MATCH(A13, 'ELI Data File'!A:A, 0))} -> Warehouse & Fulfillment | F13: =IFERROR(__xludf.DUMMYFUNCTION("AI(""Extract the Goal from the description""&D13)"),"receive inventory") -> receive inventory | G13: =IFERROR(__xludf.DUMMYFUNCTION("AI(""Extract the Value from the description""&D13)"),"newly arrived stock becomes available for allocation.") -> newly arrived stock becomes available for allocation. | H13: {=INDEX('ELI Data File'!D:D, MATCH(A13, 'ELI Data File'!A:A, 0))} -> PH-01 | J13: {=INDEX('ELI Data File'!O:O, MATCH(A13, 'ELI Data File'!A:A, 0))} -> Medium | K13: {=INDEX('ELI Data File'!P:P, MATCH(A13, 'ELI Data File'!A:A, 0))*4} -> 12 | L13: =ROUNDUP(K13*0.2,0) -> 3 | M13: =ROUNDDOWN(SUM(K13:L13)/3,0) -> 5 | N13: =SUM(K13:M13) -> 20
A14: ELI-013 | B14: {=INDEX('ELI Data File'!I:I, MATCH(A14, 'ELI Data File'!A:A, 0))} -> Inventory Management | C14: {=INDEX('ELI Data File'!J:J, MATCH(A14, 'ELI Data File'!A:A, 0))} -> Track Inventory Availability Across Sources | D14: {=INDEX('ELI Data File'!M:M, MATCH(A14, 'ELI Data File'!A:A, 0))} -> As Ops, I want to see inventory across all warehouses so I can plan multi-location fulfillment. | E14: {=INDEX('ELI Data File'!H:H, MATCH(A14, 'ELI Data File'!A:A, 0))} -> Operations / Order Management | F14: =IFERROR(__xludf.DUMMYFUNCTION("AI(""Extract the Goal from the description""&D14)"),"see inventory across all warehouses") -> see inventory across all warehouses | G14: =IFERROR(__xludf.DUMMYFUNCTION("AI(""Extract the Value from the description""&D14)"),"plan multi-location fulfillment.") -> plan multi-location fulfillment. | H14: {=INDEX('ELI Data File'!D:D, MATCH(A14, 'ELI Data File'!A:A, 0))} -> PH-01 | J14: {=INDEX('ELI Data File'!O:O, MATCH(A14, 'ELI Data File'!A:A, 0))} -> Medium | K14: {=INDEX('ELI Data File'!P:P, MATCH(A14, 'ELI Data File'!A:A, 0))*4} -> 12 | L14: =ROUNDUP(K14*0.2,0) -> 3 | M14: =ROUNDDOWN(SUM(K14:L14)/3,0) -> 5 | N14: =SUM(K14:M14) -> 20
A15: ELI-014 | B15: {=INDEX('ELI Data File'!I:I, MATCH(A15, 'ELI Data File'!A:A, 0))} -> Inventory Management | C15: {=INDEX('ELI Data File'!J:J, MATCH(A15, 'ELI Data File'!A:A, 0))} -> Track Inventory Availability Across Sources | D15: {=INDEX('ELI Data File'!M:M, MATCH(A15, 'ELI Data File'!A:A, 0))} -> As Ops, I want vendor-supplied availability included so out-of-stock items can still be sourced compliantly. | E15: {=INDEX('ELI Data File'!H:H, MATCH(A15, 'ELI Data File'!A:A, 0))} -> Operations / Order Management | F15: =IFERROR(__xludf.DUMMYFUNCTION("AI(""Extract the Goal from the description""&D15)"),"include vendor-supplied availability") -> include vendor-supplied availability | G15: =IFERROR(__xludf.DUMMYFUNCTION("AI(""Extract the Value from the description""&D15)"),"so out-of-stock items can still be sourced compliantly.") -> so out-of-stock items can still be sourced compliantly. | H15: {=INDEX('ELI Data File'!D:D, MATCH(A15, 'ELI Data File'!A:A, 0))} -> PH-01 | J15: {=INDEX('ELI Data File'!O:O, MATCH(A15, 'ELI Data File'!A:A, 0))} -> Medium | K15: {=INDEX('ELI Data File'!P:P, MATCH(A15, 'ELI Data File'!A:A, 0))*4} -> 12 | L15: =ROUNDUP(K15*0.2,0) -> 3 | M15: =ROUNDDOWN(SUM(K15:L15)/3,0) -> 5 | N15: =SUM(K15:M15) -> 20
A16: ELI-015 | B16: {=INDEX('ELI Data File'!I:I, MATCH(A16, 'ELI Data File'!A:A, 0))} -> Inventory Management | C16: {=INDEX('ELI Data File'!J:J, MATCH(A16, 'ELI Data File'!A:A, 0))} -> Track Inventory Availability Across Sources | D16: {=INDEX('ELI Data File'!M:M, MATCH(A16, 'ELI Data File'!A:A, 0))} -> As Finance, I want to distinguish allocatable inventory from informational stock so financial exposure is controlled. | E16: {=INDEX('ELI Data File'!H:H, MATCH(A16, 'ELI Data File'!A:A, 0))} -> Finance / Compliance / Admin | F16: =IFERROR(__xludf.DUMMYFUNCTION("AI(""Extract the Goal from the description""&D16)"),"distinguish allocatable inventory from informational stock") -> distinguish allocatable inventory from informational stock | G16: =IFERROR(__xludf.DUMMYFUNCTION("AI(""Extract the Value from the description""&D16)"),"financial exposure is controlled.") -> financial exposure is controlled. | H16: {=INDEX('ELI Data File'!D:D, MATCH(A16, 'ELI Data File'!A:A, 0))} -> PH-01 | J16: {=INDEX('ELI Data File'!O:O, MATCH(A16, 'ELI Data File'!A:A, 0))} -> Medium | K16: {=INDEX('ELI Data File'!P:P, MATCH(A16, 'ELI Data File'!A:A, 0))*4} -> 12 | L16: =ROUNDUP(K16*0.2,0) -> 3 | M16: =ROUNDDOWN(SUM(K16:L16)/3,0) -> 5 | N16: =SUM(K16:M16) -> 20
A17: ELI-016 | B17: {=INDEX('ELI Data File'!I:I, MATCH(A17, 'ELI Data File'!A:A, 0))} -> Inventory Management | C17: {=INDEX('ELI Data File'!J:J, MATCH(A17, 'ELI Data File'!A:A, 0))} -> Allocate Inventory to Orders | D17: {=INDEX('ELI Data File'!M:M, MATCH(A17, 'ELI Data File'!A:A, 0))} -> As Ops, I want to reserve inventory so stock is protected for committed orders. | E17: {=INDEX('ELI Data File'!H:H, MATCH(A17, 'ELI Data File'!A:A, 0))} -> Operations / Order Management | F17: =IFERROR(__xludf.DUMMYFUNCTION("AI(""Extract the Goal from the description""&D17)"),"reserve inventory") -> reserve inventory | G17: =IFERROR(__xludf.DUMMYFUNCTION("AI(""Extract the Value from the description""&D17)"),"stock is protected for committed orders.") -> stock is protected for committed orders. | H17: {=INDEX('ELI Data File'!D:D, MATCH(A17, 'ELI Data File'!A:A, 0))} -> PH-01 | J17: {=INDEX('ELI Data File'!O:O, MATCH(A17, 'ELI Data File'!A:A, 0))} -> Medium | K17: {=INDEX('ELI Data File'!P:P, MATCH(A17, 'ELI Data File'!A:A, 0))*4} -> 12 | L17: =ROUNDUP(K17*0.2,0) -> 3 | M17: =ROUNDDOWN(SUM(K17:L17)/3,0) -> 5 | N17: =SUM(K17:M17) -> 20
A18: ELI-017 | B18: {=INDEX('ELI Data File'!I:I, MATCH(A18, 'ELI Data File'!A:A, 0))} -> Inventory Management | C18: {=INDEX('ELI Data File'!J:J, MATCH(A18, 'ELI Data File'!A:A, 0))} -> Allocate Inventory to Orders | D18: {=INDEX('ELI Data File'!M:M, MATCH(A18, 'ELI Data File'!A:A, 0))} -> As Ops, I want reserved inventory released when an order is canceled so stock is reusable. | E18: {=INDEX('ELI Data File'!H:H, MATCH(A18, 'ELI Data File'!A:A, 0))} -> Operations / Order Management | F18: =IFERROR(__xludf.DUMMYFUNCTION("AI(""Extract the Goal from the description""&D18)"),"reserved inventory released when an order is canceled") -> reserved inventory released when an order is canceled | G18: =IFERROR(__xludf.DUMMYFUNCTION("AI(""Extract the Value from the description""&D18)"),"stock is reusable") -> stock is reusable | H18: {=INDEX('ELI Data File'!D:D, MATCH(A18, 'ELI Data File'!A:A, 0))} -> PH-01 | J18: {=INDEX('ELI Data File'!O:O, MATCH(A18, 'ELI Data File'!A:A, 0))} -> Medium | K18: {=INDEX('ELI Data File'!P:P, MATCH(A18, 'ELI Data File'!A:A, 0))*4} -> 12 | L18: =ROUNDUP(K18*0.2,0) -> 3 | M18: =ROUNDDOWN(SUM(K18:L18)/3,0) -> 5 | N18: =SUM(K18:M18) -> 20
A19: ELI-018 | B19: {=INDEX('ELI Data File'!I:I, MATCH(A19, 'ELI Data File'!A:A, 0))} -> Inventory Management | C19: {=INDEX('ELI Data File'!J:J, MATCH(A19, 'ELI Data File'!A:A, 0))} -> Allocate Inventory to Orders | D19: {=INDEX('ELI Data File'!M:M, MATCH(A19, 'ELI Data File'!A:A, 0))} -> As Ops, I want inventory reallocated when orders change so fulfillment remains accurate. | E19: {=INDEX('ELI Data File'!H:H, MATCH(A19, 'ELI Data File'!A:A, 0))} -> Operations / Order Management | F19: =IFERROR(__xludf.DUMMYFUNCTION("AI(""Extract the Goal from the description""&D19)"),"I want inventory reallocated when orders change") -> I want inventory reallocated when orders change | G19: =IFERROR(__xludf.DUMMYFUNCTION("AI(""Extract the Value from the description""&D19)"),"fulfillment remains accurate") -> fulfillment remains accurate | H19: {=INDEX('ELI Data File'!D:D, MATCH(A19, 'ELI Data File'!A:A, 0))} -> PH-01 | J19: {=INDEX('ELI Data File'!O:O, MATCH(A19, 'ELI Data File'!A:A, 0))} -> Medium | K19: {=INDEX('ELI Data File'!P:P, MATCH(A19, 'ELI Data File'!A:A, 0))*4} -> 12 | L19: =ROUNDUP(K19*0.2,0) -> 3 | M19: =ROUNDDOWN(SUM(K19:L19)/3,0) -> 5 | N19: =SUM(K19:M19) -> 20
A20: ELI-019 | B20: {=INDEX('ELI Data File'!I:I, MATCH(A20, 'ELI Data File'!A:A, 0))} -> Order Management | C20: {=INDEX('ELI Data File'!J:J, MATCH(A20, 'ELI Data File'!A:A, 0))} -> Create Sales Order | D20: {=INDEX('ELI Data File'!M:M, MATCH(A20, 'ELI Data File'!A:A, 0))} -> As a Sales user, I want to create a sales order tied to a customer so contract pricing and rules are applied automatically. | E20: {=INDEX('ELI Data File'!H:H, MATCH(A20, 'ELI Data File'!A:A, 0))} -> Sales / Account Management | F20: =IFERROR(__xludf.DUMMYFUNCTION("AI(""Extract the Goal from the description""&D20)"),"create a sales order tied to a customer") -> create a sales order tied to a customer | G20: =IFERROR(__xludf.DUMMYFUNCTION("AI(""Extract the Value from the description""&D20)"),"contract pricing and rules are applied automatically.") -> contract pricing and rules are applied automatically. | H20: {=INDEX('ELI Data File'!D:D, MATCH(A20, 'ELI Data File'!A:A, 0))} -> PH-01 | J20: {=INDEX('ELI Data File'!O:O, MATCH(A20, 'ELI Data File'!A:A, 0))} -> Medium | K20: {=INDEX('ELI Data File'!P:P, MATCH(A20, 'ELI Data File'!A:A, 0))*4} -> 12 | L20: =ROUNDUP(K20*0.2,0) -> 3 | M20: =ROUNDDOWN(SUM(K20:L20)/3,0) -> 5 | N20: =SUM(K20:M20) -> 20
A21: ELI-020 | B21: {=INDEX('ELI Data File'!I:I, MATCH(A21, 'ELI Data File'!A:A, 0))} -> Order Management | C21: {=INDEX('ELI Data File'!J:J, MATCH(A21, 'ELI Data File'!A:A, 0))} -> Create Sales Order | D21: {=INDEX('ELI Data File'!M:M, MATCH(A21, 'ELI Data File'!A:A, 0))} -> As a Sales user, I want required order data validated so incomplete orders cannot proceed. | E21: {=INDEX('ELI Data File'!H:H, MATCH(A21, 'ELI Data File'!A:A, 0))} -> Sales / Account Management | F21: =IFERROR(__xludf.DUMMYFUNCTION("AI(""Extract the Goal from the description""&D21)"),"required order data validated") -> required order data validated | G21: =IFERROR(__xludf.DUMMYFUNCTION("AI(""Extract the Value from the description""&D21)"),"incomplete orders cannot proceed.") -> incomplete orders cannot proceed. | H21: {=INDEX('ELI Data File'!D:D, MATCH(A21, 'ELI Data File'!A:A, 0))} -> PH-01 | J21: {=INDEX('ELI Data File'!O:O, MATCH(A21, 'ELI Data File'!A:A, 0))} -> Medium | K21: {=INDEX('ELI Data File'!P:P, MATCH(A21, 'ELI Data File'!A:A, 0))*4} -> 12 | L21: =ROUNDUP(K21*0.2,0) -> 3 | M21: =ROUNDDOWN(SUM(K21:L21)/3,0) -> 5 | N21: =SUM(K21:M21) -> 20
A22: ELI-021 | B22: {=INDEX('ELI Data File'!I:I, MATCH(A22, 'ELI Data File'!A:A, 0))} -> Order Management | C22: {=INDEX('ELI Data File'!J:J, MATCH(A22, 'ELI Data File'!A:A, 0))} -> Create Sales Order | D22: {=INDEX('ELI Data File'!M:M, MATCH(A22, 'ELI Data File'!A:A, 0))} -> As a Sales user, I want to preview pricing so I can confirm totals before submitting the order. | E22: {=INDEX('ELI Data File'!H:H, MATCH(A22, 'ELI Data File'!A:A, 0))} -> Sales / Account Management | F22: =IFERROR(__xludf.DUMMYFUNCTION("AI(""Extract the Goal from the description""&D22)"),"preview pricing") -> preview pricing | G22: =IFERROR(__xludf.DUMMYFUNCTION("AI(""Extract the Value from the description""&D22)"),"confirm totals before submitting the order.") -> confirm totals before submitting the order. | H22: {=INDEX('ELI Data File'!D:D, MATCH(A22, 'ELI Data File'!A:A, 0))} -> PH-01 | J22: {=INDEX('ELI Data File'!O:O, MATCH(A22, 'ELI Data File'!A:A, 0))} -> Medium | K22: {=INDEX('ELI Data File'!P:P, MATCH(A22, 'ELI Data File'!A:A, 0))*4} -> 12 | L22: =ROUNDUP(K22*0.2,0) -> 3 | M22: =ROUNDDOWN(SUM(K22:L22)/3,0) -> 5 | N22: =SUM(K22:M22) -> 20
A23: ELI-022 | B23: {=INDEX('ELI Data File'!I:I, MATCH(A23, 'ELI Data File'!A:A, 0))} -> Order Management | C23: {=INDEX('ELI Data File'!J:J, MATCH(A23, 'ELI Data File'!A:A, 0))} -> Evaluate Contract Pricing & Terms | D23: {=INDEX('ELI Data File'!M:M, MATCH(A23, 'ELI Data File'!A:A, 0))} -> As Finance, I want tiered pricing applied automatically so pricing is consistent and auditable. | E23: {=INDEX('ELI Data File'!H:H, MATCH(A23, 'ELI Data File'!A:A, 0))} -> Finance / Compliance / Admin | F23: =IFERROR(__xludf.DUMMYFUNCTION("AI(""Extract the Goal from the description""&D23)"),"apply tiered pricing automatically") -> apply tiered pricing automatically | G23: =IFERROR(__xludf.DUMMYFUNCTION("AI(""Extract the Value from the description""&D23)"),"pricing is consistent and auditable.") -> pricing is consistent and auditable. | H23: {=INDEX('ELI Data File'!D:D, MATCH(A23, 'ELI Data File'!A:A, 0))} -> PH-01 | J23: {=INDEX('ELI Data File'!O:O, MATCH(A23, 'ELI Data File'!A:A, 0))} -> Medium | K23: {=INDEX('ELI Data File'!P:P, MATCH(A23, 'ELI Data File'!A:A, 0))*4} -> 12 | L23: =ROUNDUP(K23*0.2,0) -> 3 | M23: =ROUNDDOWN(SUM(K23:L23)/3,0) -> 5 | N23: =SUM(K23:M23) -> 20
A24: ELI-023 | B24: {=INDEX('ELI Data File'!I:I, MATCH(A24, 'ELI Data File'!A:A, 0))} -> Order Management | C24: {=INDEX('ELI Data File'!J:J, MATCH(A24, 'ELI Data File'!A:A, 0))} -> Evaluate Contract Pricing & Terms | D24: {=INDEX('ELI Data File'!M:M, MATCH(A24, 'ELI Data File'!A:A, 0))} -> As Finance, I want rebates and penalties enforced so margins and commitments are protected. | E24: {=INDEX('ELI Data File'!H:H, MATCH(A24, 'ELI Data File'!A:A, 0))} -> Finance / Compliance / Admin | F24: =IFERROR(__xludf.DUMMYFUNCTION("AI(""Extract the Goal from the description""&D24)"),"rebates and penalties enforced") -> rebates and penalties enforced | G24: =IFERROR(__xludf.DUMMYFUNCTION("AI(""Extract the Value from the description""&D24)"),"margins and commitments are protected.") -> margins and commitments are protected. | H24: {=INDEX('ELI Data File'!D:D, MATCH(A24, 'ELI Data File'!A:A, 0))} -> PH-01 | J24: {=INDEX('ELI Data File'!O:O, MATCH(A24, 'ELI Data File'!A:A, 0))} -> Medium | K24: {=INDEX('ELI Data File'!P:P, MATCH(A24, 'ELI Data File'!A:A, 0))*4} -> 12 | L24: =ROUNDUP(K24*0.2,0) -> 3 | M24: =ROUNDDOWN(SUM(K24:L24)/3,0) -> 5 | N24: =SUM(K24:M24) -> 20
A25: ELI-024 | B25: {=INDEX('ELI Data File'!I:I, MATCH(A25, 'ELI Data File'!A:A, 0))} -> Order Management | C25: {=INDEX('ELI Data File'!J:J, MATCH(A25, 'ELI Data File'!A:A, 0))} -> Evaluate Contract Pricing & Terms | D25: {=INDEX('ELI Data File'!M:M, MATCH(A25, 'ELI Data File'!A:A, 0))} -> As Ops, I want pricing recalculated when an order changes so pricing remains accurate. | E25: {=INDEX('ELI Data File'!H:H, MATCH(A25, 'ELI Data File'!A:A, 0))} -> Operations / Order Management | F25: =IFERROR(__xludf.DUMMYFUNCTION("AI(""Extract the Goal from the description""&D25)"),"recalculated when an order changes") -> recalculated when an order changes | G25: =IFERROR(__xludf.DUMMYFUNCTION("AI(""Extract the Value from the description""&D25)"),"pricing remains accurate.") -> pricing remains accurate. | H25: {=INDEX('ELI Data File'!D:D, MATCH(A25, 'ELI Data File'!A:A, 0))} -> PH-01 | J25: {=INDEX('ELI Data File'!O:O, MATCH(A25, 'ELI Data File'!A:A, 0))} -> Medium | K25: {=INDEX('ELI Data File'!P:P, MATCH(A25, 'ELI Data File'!A:A, 0))*4} -> 12 | L25: =ROUNDUP(K25*0.2,0) -> 3 | M25: =ROUNDDOWN(SUM(K25:L25)/3,0) -> 5 | N25: =SUM(K25:M25) -> 20
A26: ELI-025 | B26: {=INDEX('ELI Data File'!I:I, MATCH(A26, 'ELI Data File'!A:A, 0))} -> Order Management | C26: {=INDEX('ELI Data File'!J:J, MATCH(A26, 'ELI Data File'!A:A, 0))} -> Manage Sales Order Lifecycle | D26: {=INDEX('ELI Data File'!M:M, MATCH(A26, 'ELI Data File'!A:A, 0))} -> As Ops, I want to view order status so I can track progress without manual follow-up. | E26: {=INDEX('ELI Data File'!H:H, MATCH(A26, 'ELI Data File'!A:A, 0))} -> Operations / Order Management | F26: =IFERROR(__xludf.DUMMYFUNCTION("AI(""Extract the Goal from the description""&D26)"),"view order status") -> view order status | G26: =IFERROR(__xludf.DUMMYFUNCTION("AI(""Extract the Value from the description""&D26)"),"track progress without manual follow-up.") -> track progress without manual follow-up. | H26: {=INDEX('ELI Data File'!D:D, MATCH(A26, 'ELI Data File'!A:A, 0))} -> PH-01 | J26: {=INDEX('ELI Data File'!O:O, MATCH(A26, 'ELI Data File'!A:A, 0))} -> Medium | K26: {=INDEX('ELI Data File'!P:P, MATCH(A26, 'ELI Data File'!A:A, 0))*4} -> 12 | L26: =ROUNDUP(K26*0.2,0) -> 3 | M26: =ROUNDDOWN(SUM(K26:L26)/3,0) -> 5 | N26: =SUM(K26:M26) -> 20
A27: ELI-026 | B27: {=INDEX('ELI Data File'!I:I, MATCH(A27, 'ELI Data File'!A:A, 0))} -> Order Management | C27: {=INDEX('ELI Data File'!J:J, MATCH(A27, 'ELI Data File'!A:A, 0))} -> Manage Sales Order Lifecycle | D27: {=INDEX('ELI Data File'!M:M, MATCH(A27, 'ELI Data File'!A:A, 0))} -> As Ops, I want to update order status so downstream processes stay aligned. | E27: {=INDEX('ELI Data File'!H:H, MATCH(A27, 'ELI Data File'!A:A, 0))} -> Operations / Order Management | F27: =IFERROR(__xludf.DUMMYFUNCTION("AI(""Extract the Goal from the description""&D27)"),"update order status") -> update order status | G27: =IFERROR(__xludf.DUMMYFUNCTION("AI(""Extract the Value from the description""&D27)"),"downstream processes stay aligned") -> downstream processes stay aligned | H27: {=INDEX('ELI Data File'!D:D, MATCH(A27, 'ELI Data File'!A:A, 0))} -> PH-01 | J27: {=INDEX('ELI Data File'!O:O, MATCH(A27, 'ELI Data File'!A:A, 0))} -> Medium | K27: {=INDEX('ELI Data File'!P:P, MATCH(A27, 'ELI Data File'!A:A, 0))*4} -> 12 | L27: =ROUNDUP(K27*0.2,0) -> 3 | M27: =ROUNDDOWN(SUM(K27:L27)/3,0) -> 5 | N27: =SUM(K27:M27) -> 20
A28: ELI-027 | B28: {=INDEX('ELI Data File'!I:I, MATCH(A28, 'ELI Data File'!A:A, 0))} -> Order Management | C28: {=INDEX('ELI Data File'!J:J, MATCH(A28, 'ELI Data File'!A:A, 0))} -> Manage Sales Order Lifecycle | D28: {=INDEX('ELI Data File'!M:M, MATCH(A28, 'ELI Data File'!A:A, 0))} -> As Sales, I want to cancel an order so inventory and commitments are released correctly. | E28: {=INDEX('ELI Data File'!H:H, MATCH(A28, 'ELI Data File'!A:A, 0))} -> Sales / Account Management | F28: =IFERROR(__xludf.DUMMYFUNCTION("AI(""Extract the Goal from the description""&D28)"),"cancel an order") -> cancel an order | G28: =IFERROR(__xludf.DUMMYFUNCTION("AI(""Extract the Value from the description""&D28)"),"inventory and commitments are released correctly.") -> inventory and commitments are released correctly. | H28: {=INDEX('ELI Data File'!D:D, MATCH(A28, 'ELI Data File'!A:A, 0))} -> PH-01 | J28: {=INDEX('ELI Data File'!O:O, MATCH(A28, 'ELI Data File'!A:A, 0))} -> Medium | K28: {=INDEX('ELI Data File'!P:P, MATCH(A28, 'ELI Data File'!A:A, 0))*4} -> 12 | L28: =ROUNDUP(K28*0.2,0) -> 3 | M28: =ROUNDDOWN(SUM(K28:L28)/3,0) -> 5 | N28: =SUM(K28:M28) -> 20
A29: ELI-028 | B29: {=INDEX('ELI Data File'!I:I, MATCH(A29, 'ELI Data File'!A:A, 0))} -> Order Management | C29: {=INDEX('ELI Data File'!J:J, MATCH(A29, 'ELI Data File'!A:A, 0))} -> Approve Order Exceptions & Overrides | D29: {=INDEX('ELI Data File'!M:M, MATCH(A29, 'ELI Data File'!A:A, 0))} -> As Finance, I want orders that exceed thresholds routed for approval so risk is controlled. | E29: {=INDEX('ELI Data File'!H:H, MATCH(A29, 'ELI Data File'!A:A, 0))} -> Finance / Compliance / Admin | F29: =IFERROR(__xludf.DUMMYFUNCTION("AI(""Extract the Goal from the description""&D29)"),"orders that exceed thresholds routed for approval") -> orders that exceed thresholds routed for approval | G29: =IFERROR(__xludf.DUMMYFUNCTION("AI(""Extract the Value from the description""&D29)"),"risk is controlled") -> risk is controlled | H29: {=INDEX('ELI Data File'!D:D, MATCH(A29, 'ELI Data File'!A:A, 0))} -> PH-01 | J29: {=INDEX('ELI Data File'!O:O, MATCH(A29, 'ELI Data File'!A:A, 0))} -> Medium | K29: {=INDEX('ELI Data File'!P:P, MATCH(A29, 'ELI Data File'!A:A, 0))*4} -> 12 | L29: =ROUNDUP(K29*0.2,0) -> 3 | M29: =ROUNDDOWN(SUM(K29:L29)/3,0) -> 5 | N29: =SUM(K29:M29) -> 20
A30: ELI-029 | B30: {=INDEX('ELI Data File'!I:I, MATCH(A30, 'ELI Data File'!A:A, 0))} -> Order Management | C30: {=INDEX('ELI Data File'!J:J, MATCH(A30, 'ELI Data File'!A:A, 0))} -> Approve Order Exceptions & Overrides | D30: {=INDEX('ELI Data File'!M:M, MATCH(A30, 'ELI Data File'!A:A, 0))} -> As Finance, I want to approve or reject exceptions so decisions are explicit and traceable. | E30: {=INDEX('ELI Data File'!H:H, MATCH(A30, 'ELI Data File'!A:A, 0))} -> Finance / Compliance / Admin | F30: =IFERROR(__xludf.DUMMYFUNCTION("AI(""Extract the Goal from the description""&D30)"),"approve or reject exceptions") -> approve or reject exceptions | G30: =IFERROR(__xludf.DUMMYFUNCTION("AI(""Extract the Value from the description""&D30)"),"decisions are explicit and traceable.") -> decisions are explicit and traceable. | H30: {=INDEX('ELI Data File'!D:D, MATCH(A30, 'ELI Data File'!A:A, 0))} -> PH-01 | J30: {=INDEX('ELI Data File'!O:O, MATCH(A30, 'ELI Data File'!A:A, 0))} -> Medium | K30: {=INDEX('ELI Data File'!P:P, MATCH(A30, 'ELI Data File'!A:A, 0))*4} -> 12 | L30: =ROUNDUP(K30*0.2,0) -> 3 | M30: =ROUNDDOWN(SUM(K30:L30)/3,0) -> 5 | N30: =SUM(K30:M30) -> 20
A31: ELI-030 | B31: {=INDEX('ELI Data File'!I:I, MATCH(A31, 'ELI Data File'!A:A, 0))} -> Order Management | C31: {=INDEX('ELI Data File'!J:J, MATCH(A31, 'ELI Data File'!A:A, 0))} -> Approve Order Exceptions & Overrides | D31: {=INDEX('ELI Data File'!M:M, MATCH(A31, 'ELI Data File'!A:A, 0))} -> As Finance, I want an audit trail of approvals so reviews do not rely on email chains. | E31: {=INDEX('ELI Data File'!H:H, MATCH(A31, 'ELI Data File'!A:A, 0))} -> Finance / Compliance / Admin | F31: =IFERROR(__xludf.DUMMYFUNCTION("AI(""Extract the Goal from the description""&D31)"),"view an audit trail of approvals") -> view an audit trail of approvals | G31: =IFERROR(__xludf.DUMMYFUNCTION("AI(""Extract the Value from the description""&D31)"),"reviews do not rely on email chains.") -> reviews do not rely on email chains. | H31: {=INDEX('ELI Data File'!D:D, MATCH(A31, 'ELI Data File'!A:A, 0))} -> PH-01 | J31: {=INDEX('ELI Data File'!O:O, MATCH(A31, 'ELI Data File'!A:A, 0))} -> Medium | K31: {=INDEX('ELI Data File'!P:P, MATCH(A31, 'ELI Data File'!A:A, 0))*4} -> 12 | L31: =ROUNDUP(K31*0.2,0) -> 3 | M31: =ROUNDDOWN(SUM(K31:L31)/3,0) -> 5 | N31: =SUM(K31:M31) -> 20
A32: ELI-031 | B32: {=INDEX('ELI Data File'!I:I, MATCH(A32, 'ELI Data File'!A:A, 0))} -> Fulfillment Orchestration | C32: {=INDEX('ELI Data File'!J:J, MATCH(A32, 'ELI Data File'!A:A, 0))} -> Execute Fulfillment | D32: {=INDEX('ELI Data File'!M:M, MATCH(A32, 'ELI Data File'!A:A, 0))} -> As Ops, I want orders assigned to the appropriate fulfillment resource so execution begins without manual routing. | E32: {=INDEX('ELI Data File'!H:H, MATCH(A32, 'ELI Data File'!A:A, 0))} -> Operations / Order Management | F32: =IFERROR(__xludf.DUMMYFUNCTION("AI(""Extract the Goal from the description""&D32)"),"orders assigned to the appropriate fulfillment resource") -> orders assigned to the appropriate fulfillment resource | G32: =IFERROR(__xludf.DUMMYFUNCTION("AI(""Extract the Value from the description""&D32)"),"execution begins without manual routing.") -> execution begins without manual routing. | H32: {=INDEX('ELI Data File'!D:D, MATCH(A32, 'ELI Data File'!A:A, 0))} -> PH-01 | J32: {=INDEX('ELI Data File'!O:O, MATCH(A32, 'ELI Data File'!A:A, 0))} -> Medium | K32: {=INDEX('ELI Data File'!P:P, MATCH(A32, 'ELI Data File'!A:A, 0))*4} -> 12 | L32: =ROUNDUP(K32*0.2,0) -> 3 | M32: =ROUNDDOWN(SUM(K32:L32)/3,0) -> 5 | N32: =SUM(K32:M32) -> 20
A33: ELI-032 | B33: {=INDEX('ELI Data File'!I:I, MATCH(A33, 'ELI Data File'!A:A, 0))} -> Fulfillment Orchestration | C33: {=INDEX('ELI Data File'!J:J, MATCH(A33, 'ELI Data File'!A:A, 0))} -> Execute Fulfillment | D33: {=INDEX('ELI Data File'!M:M, MATCH(A33, 'ELI Data File'!A:A, 0))} -> As a Warehouse user, I want system-generated pick instructions so I can fulfill orders accurately. | E33: {=INDEX('ELI Data File'!H:H, MATCH(A33, 'ELI Data File'!A:A, 0))} -> Warehouse & Fulfillment | F33: =IFERROR(__xludf.DUMMYFUNCTION("AI(""Extract the Goal from the description""&D33)"),"system-generated pick instructions") -> system-generated pick instructions | G33: =IFERROR(__xludf.DUMMYFUNCTION("AI(""Extract the Value from the description""&D33)"),"fulfill orders accurately.") -> fulfill orders accurately. | H33: {=INDEX('ELI Data File'!D:D, MATCH(A33, 'ELI Data File'!A:A, 0))} -> PH-01 | J33: {=INDEX('ELI Data File'!O:O, MATCH(A33, 'ELI Data File'!A:A, 0))} -> Medium | K33: {=INDEX('ELI Data File'!P:P, MATCH(A33, 'ELI Data File'!A:A, 0))*4} -> 12 | L33: =ROUNDUP(K33*0.2,0) -> 3 | M33: =ROUNDDOWN(SUM(K33:L33)/3,0) -> 5 | N33: =SUM(K33:M33) -> 20
A34: ELI-033 | B34: {=INDEX('ELI Data File'!I:I, MATCH(A34, 'ELI Data File'!A:A, 0))} -> Fulfillment Orchestration | C34: {=INDEX('ELI Data File'!J:J, MATCH(A34, 'ELI Data File'!A:A, 0))} -> Execute Fulfillment | D34: {=INDEX('ELI Data File'!M:M, MATCH(A34, 'ELI Data File'!A:A, 0))} -> As a Warehouse user, I want to pack and ship orders so delivery proceeds according to service levels. | E34: {=INDEX('ELI Data File'!H:H, MATCH(A34, 'ELI Data File'!A:A, 0))} -> Warehouse & Fulfillment | F34: =IFERROR(__xludf.DUMMYFUNCTION("AI(""Extract the Goal from the description""&D34)"),"pack and ship orders") -> pack and ship orders | G34: =IFERROR(__xludf.DUMMYFUNCTION("AI(""Extract the Value from the description""&D34)"),"delivery proceeds according to service levels.") -> delivery proceeds according to service levels. | H34: {=INDEX('ELI Data File'!D:D, MATCH(A34, 'ELI Data File'!A:A, 0))} -> PH-01 | J34: {=INDEX('ELI Data File'!O:O, MATCH(A34, 'ELI Data File'!A:A, 0))} -> Medium | K34: {=INDEX('ELI Data File'!P:P, MATCH(A34, 'ELI Data File'!A:A, 0))*4} -> 12 | L34: =ROUNDUP(K34*0.2,0) -> 3 | M34: =ROUNDDOWN(SUM(K34:L34)/3,0) -> 5 | N34: =SUM(K34:M34) -> 20
A35: ELI-034 | B35: {=INDEX('ELI Data File'!I:I, MATCH(A35, 'ELI Data File'!A:A, 0))} -> Fulfillment Orchestration | C35: {=INDEX('ELI Data File'!J:J, MATCH(A35, 'ELI Data File'!A:A, 0))} -> Determine Fulfillment Routing | D35: {=INDEX('ELI Data File'!M:M, MATCH(A35, 'ELI Data File'!A:A, 0))} -> As Ops, I want the system to select the optimal fulfillment path so cost and SLA requirements are met. | E35: {=INDEX('ELI Data File'!H:H, MATCH(A35, 'ELI Data File'!A:A, 0))} -> Operations / Order Management | F35: =IFERROR(__xludf.DUMMYFUNCTION("AI(""Extract the Goal from the description""&D35)"),"select the optimal fulfillment path") -> select the optimal fulfillment path | G35: =IFERROR(__xludf.DUMMYFUNCTION("AI(""Extract the Value from the description""&D35)"),"cost and SLA requirements are met.") -> cost and SLA requirements are met. | H35: {=INDEX('ELI Data File'!D:D, MATCH(A35, 'ELI Data File'!A:A, 0))} -> PH-01 | J35: {=INDEX('ELI Data File'!O:O, MATCH(A35, 'ELI Data File'!A:A, 0))} -> Medium | K35: {=INDEX('ELI Data File'!P:P, MATCH(A35, 'ELI Data File'!A:A, 0))*4} -> 12 | L35: =ROUNDUP(K35*0.2,0) -> 3 | M35: =ROUNDDOWN(SUM(K35:L35)/3,0) -> 5 | N35: =SUM(K35:M35) -> 20
A36: ELI-035 | B36: {=INDEX('ELI Data File'!I:I, MATCH(A36, 'ELI Data File'!A:A, 0))} -> Fulfillment Orchestration | C36: {=INDEX('ELI Data File'!J:J, MATCH(A36, 'ELI Data File'!A:A, 0))} -> Determine Fulfillment Routing | D36: {=INDEX('ELI Data File'!M:M, MATCH(A36, 'ELI Data File'!A:A, 0))} -> As Ops, I want orders split across sources when necessary so commitments are met. | E36: {=INDEX('ELI Data File'!H:H, MATCH(A36, 'ELI Data File'!A:A, 0))} -> Operations / Order Management | F36: =IFERROR(__xludf.DUMMYFUNCTION("AI(""Extract the Goal from the description""&D36)"),"split orders across sources when necessary") -> split orders across sources when necessary | G36: =IFERROR(__xludf.DUMMYFUNCTION("AI(""Extract the Value from the description""&D36)"),"commitments are met") -> commitments are met | H36: {=INDEX('ELI Data File'!D:D, MATCH(A36, 'ELI Data File'!A:A, 0))} -> PH-01 | J36: {=INDEX('ELI Data File'!O:O, MATCH(A36, 'ELI Data File'!A:A, 0))} -> Medium | K36: {=INDEX('ELI Data File'!P:P, MATCH(A36, 'ELI Data File'!A:A, 0))*4} -> 12 | L36: =ROUNDUP(K36*0.2,0) -> 3 | M36: =ROUNDDOWN(SUM(K36:L36)/3,0) -> 5 | N36: =SUM(K36:M36) -> 20
A37: ELI-036 | B37: {=INDEX('ELI Data File'!I:I, MATCH(A37, 'ELI Data File'!A:A, 0))} -> Fulfillment Orchestration | C37: {=INDEX('ELI Data File'!J:J, MATCH(A37, 'ELI Data File'!A:A, 0))} -> Determine Fulfillment Routing | D37: {=INDEX('ELI Data File'!M:M, MATCH(A37, 'ELI Data File'!A:A, 0))} -> As Finance, I want service-level constraints enforced so contractual obligations are met. | E37: {=INDEX('ELI Data File'!H:H, MATCH(A37, 'ELI Data File'!A:A, 0))} -> Finance / Compliance / Admin | F37: =IFERROR(__xludf.DUMMYFUNCTION("AI(""Extract the Goal from the description""&D37)"),"service-level constraints enforced") -> service-level constraints enforced | G37: =IFERROR(__xludf.DUMMYFUNCTION("AI(""Extract the Value from the description""&D37)"),"contractual obligations are met.") -> contractual obligations are met. | H37: {=INDEX('ELI Data File'!D:D, MATCH(A37, 'ELI Data File'!A:A, 0))} -> PH-01 | J37: {=INDEX('ELI Data File'!O:O, MATCH(A37, 'ELI Data File'!A:A, 0))} -> Medium | K37: {=INDEX('ELI Data File'!P:P, MATCH(A37, 'ELI Data File'!A:A, 0))*4} -> 12 | L37: =ROUNDUP(K37*0.2,0) -> 3 | M37: =ROUNDDOWN(SUM(K37:L37)/3,0) -> 5 | N37: =SUM(K37:M37) -> 20
A38: ELI-037 | B38: {=INDEX('ELI Data File'!I:I, MATCH(A38, 'ELI Data File'!A:A, 0))} -> Fulfillment Orchestration | C38: {=INDEX('ELI Data File'!J:J, MATCH(A38, 'ELI Data File'!A:A, 0))} -> Validate Regulated Substitutions | D38: {=INDEX('ELI Data File'!M:M, MATCH(A38, 'ELI Data File'!A:A, 0))} -> As Ops, I want the system to propose allowed substitutions so I don’t manually assess eligibility. | E38: {=INDEX('ELI Data File'!H:H, MATCH(A38, 'ELI Data File'!A:A, 0))} -> Operations / Order Management | F38: =IFERROR(__xludf.DUMMYFUNCTION("AI(""Extract the Goal from the description""&D38)"),"the system to propose allowed substitutions") -> the system to propose allowed substitutions | G38: =IFERROR(__xludf.DUMMYFUNCTION("AI(""Extract the Value from the description""&D38)"),"I don't manually assess eligibility.") -> I don't manually assess eligibility. | H38: {=INDEX('ELI Data File'!D:D, MATCH(A38, 'ELI Data File'!A:A, 0))} -> PH-01 | J38: {=INDEX('ELI Data File'!O:O, MATCH(A38, 'ELI Data File'!A:A, 0))} -> Medium | K38: {=INDEX('ELI Data File'!P:P, MATCH(A38, 'ELI Data File'!A:A, 0))*4} -> 12 | L38: =ROUNDUP(K38*0.2,0) -> 3 | M38: =ROUNDDOWN(SUM(K38:L38)/3,0) -> 5 | N38: =SUM(K38:M38) -> 20
A39: ELI-038 | B39: {=INDEX('ELI Data File'!I:I, MATCH(A39, 'ELI Data File'!A:A, 0))} -> Fulfillment Orchestration | C39: {=INDEX('ELI Data File'!J:J, MATCH(A39, 'ELI Data File'!A:A, 0))} -> Validate Regulated Substitutions | D39: {=INDEX('ELI Data File'!M:M, MATCH(A39, 'ELI Data File'!A:A, 0))} -> As Compliance, I want vendor certifications validated so non-compliant substitutions are blocked. | E39: {=INDEX('ELI Data File'!H:H, MATCH(A39, 'ELI Data File'!A:A, 0))} -> Finance / Compliance / Admin | F39: =IFERROR(__xludf.DUMMYFUNCTION("AI(""Extract the Goal from the description""&D39)"),"vendor certifications validated") -> vendor certifications validated | G39: =IFERROR(__xludf.DUMMYFUNCTION("AI(""Extract the Value from the description""&D39)"),"non-compliant substitutions are blocked.") -> non-compliant substitutions are blocked. | H39: {=INDEX('ELI Data File'!D:D, MATCH(A39, 'ELI Data File'!A:A, 0))} -> PH-01 | J39: {=INDEX('ELI Data File'!O:O, MATCH(A39, 'ELI Data File'!A:A, 0))} -> Medium | K39: {=INDEX('ELI Data File'!P:P, MATCH(A39, 'ELI Data File'!A:A, 0))*4} -> 12 | L39: =ROUNDUP(K39*0.2,0) -> 3 | M39: =ROUNDDOWN(SUM(K39:L39)/3,0) -> 5 | N39: =SUM(K39:M39) -> 20
A40: ELI-039 | B40: {=INDEX('ELI Data File'!I:I, MATCH(A40, 'ELI Data File'!A:A, 0))} -> Fulfillment Orchestration | C40: {=INDEX('ELI Data File'!J:J, MATCH(A40, 'ELI Data File'!A:A, 0))} -> Validate Regulated Substitutions | D40: {=INDEX('ELI Data File'!M:M, MATCH(A40, 'ELI Data File'!A:A, 0))} -> As Compliance, I want geographic and regulatory rules enforced so orders comply with applicable laws. | E40: {=INDEX('ELI Data File'!H:H, MATCH(A40, 'ELI Data File'!A:A, 0))} -> Finance / Compliance / Admin | F40: =IFERROR(__xludf.DUMMYFUNCTION("AI(""Extract the Goal from the description""&D40)"),"geographic and regulatory rules enforced") -> geographic and regulatory rules enforced | G40: =IFERROR(__xludf.DUMMYFUNCTION("AI(""Extract the Value from the description""&D40)"),"orders comply with applicable laws.") -> orders comply with applicable laws. | H40: {=INDEX('ELI Data File'!D:D, MATCH(A40, 'ELI Data File'!A:A, 0))} -> PH-01 | J40: {=INDEX('ELI Data File'!O:O, MATCH(A40, 'ELI Data File'!A:A, 0))} -> Medium | K40: {=INDEX('ELI Data File'!P:P, MATCH(A40, 'ELI Data File'!A:A, 0))*4} -> 12 | L40: =ROUNDUP(K40*0.2,0) -> 3 | M40: =ROUNDDOWN(SUM(K40:L40)/3,0) -> 5 | N40: =SUM(K40:M40) -> 20
...

Sheet ELI Data File
A1: ELI ID | B1: Strategy Ref | C1: Blueprint Ref | D1: Phase Ref ID | E1: Deliverable ID | F1: Epic ID | G1: User Group ID | H1: User Group Name | I1: Deliverable Name | J1: Epic Name | K1: ELI Name | L1: ELI Type | M1: ELI Description | N1: Notes | O1: Complexity | P1: Effort | Q1: Tech Hours | R1: SA Hours
A2: ELI-001 | B2: FUNC-001 | C2: BP-1765865704672 | D2: PH-01 | E2: DEL-001 | F2: EPIC-010 | H2: Sales / Account Management | I2: Customer Management | J2: Manage Customers | K2: Create a Customer Profile | L2: User Story | M2: As a Sales user, I want to create a customer profile so that orders can be associated with the correct legal and billing entity. | O2: Medium | P2: 3 | Q2: 4 | R2: =Q2*0.2 -> 0.8
